Workbook

Sheet DATA
C2: EMPLOYEE DATA
C5: Employee Name | E5: : | F5: Annas Putra Anuraga
C6: Employee No. | E6: : | F6: POJ42050260
C7: Company Name | E7: : | F7: PT Pesonna Optima Jasa
C8: Client Site | E8: : | F8: Divisi Pengembangan Aplikasi TI - PT Pegadaian
C9: Work Unit | E9: : | F9: Dept. IT Bussines Analyst
C10: Dept. Head Name | E10: : | F10: Andhar Setiawan
C11: Supervisor | E11: : | F11: Lailatul Fitriana R
C12: Squad | E12: : | F12: Pooling Core
C13: Report Period | E13: : | F13: MARCH | I13: to | J13: APRIL

Sheet PERHITUNGAN LEMBAR KERJA
A2: REKAPITULASI PERHITUNGAN LEMBAR KERJA
A3: =DATA!F7 -> PT Pesonna Optima Jasa
A6: Client Site | D6: : | E6: =DATA!F8 -> Divisi Pengembangan Aplikasi TI - PT Pegadaian | X6: Squad | AB6: : | AC6: =DATA!F12 -> Pooling Core
A7: Work Unit | D7: : | E7: =DATA!F9 -> Dept. IT Bussines Analyst | X7: Employee Name | AB7: : | AC7: =DATA!F5 -> Annas Putra Anuraga
A8: Dept. Head Name | D8: : | E8: =DATA!F10 -> Andhar Setiawan | X8: Employee Number | AB8: : | AC8: =DATA!F6 -> POJ42050260
A9: Supervisor | D9: : | E9: =DATA!F11 -> Lailatul Fitriana R | X9: Month | AB9: : | AC9: =DATA!F13 -> MARCH | AG9: to | AH9: =DATA!J13 -> APRIL
A11: Date | H11: 26 | I11: 27 | J11: 28 | K11: 29 | L11: 30 | M11: 31 | N11: 1 | O11: 2 | P11: 3 | Q11: 4 | R11: 5 | S11: 6 | T11: 7 | U11: 8 | V11: 9 | W11: 10 | X11: 11 | Y11: 12 | Z11: 13 | AA11: 14 | AB11: 15 | AC11: 16 | AD11: 17 | AE11: 18 | AF11: 19 | AG11: 20 | AH11: 21 | AI11: 22 | AJ11: 23 | AK11: 24 | AL11: 25
A13: WH | B13: - Work Hours | H13: 8 | I13: 8 | J13: W | K13: W | L13: 8 | M13: 8 | N13: 8 | O13: 8 | P13: H | Q13: W | R13: H | S13: 8 | T13: 8 | U13: 8 | V13: 8 | W13: 8 | X13: W | Y13: W | Z13: 8 | AA13: 8 | AB13: 8 | AC13: 8 | AD13: 8 | AE13: W | AF13: W | AG13: 8 | AH13: 8 | AI13: 8 | AJ13: 8 | AK13: 8 | AL13: W
A14: OT | B14: - Over Time
A16: H | B16: - Holidays
A17: AL | B17: - Annual Leave
A18: S | B18: - Sick Leave
A19: U | B19: - Unpaid Leave
A20: C | B20: - Comp. Off
A21: W | B21: - Weekend
A23: Total | H23: 8 | I23: 8 | J23: W | K23: W | L23: 8 | M23: 8 | N23: 8 | O23: 8 | P23: H | Q23: W | R23: H | S23: 8 | T23: 8 | U23: 8 | V23: 8 | W23: 8 | X23: W | Y23: W | Z23: 8 | AA23: 8 | AB23: 8 | AC23: 8 | AD23: 8 | AE23: W | AF23: W | AG23: 8 | AH23: 8 | AI23: 8 | AJ23: 8 | AK23: 8 | AL23: W
A24: Please write the corresponding alphabets (AL for Annual Leave, S for Sick Leave, C for Comp Off, etc) against the appropriate date.
A26: RECAP | H26: Hours | J26: Days | M26: I CERTIFY THAT THE ABOVE IS A TRUE RECORD OF MY TIME FOR THIS PERIOD | AE26: NOTES:
A27: WH | B27: - Work Hours | H27: =SUM(H13:AL13) -> 168 | J27: =H27/8 -> 21 | M27: FROM | N27: =AC9 -> MARCH | P27: TO | Q27: =AH9 -> APRIL
A28: OT | B28: - Over Time | H28: =SUM(H14:AL14) -> 0 | J28: =H28/8 -> 0 | M28: Employee | S28: Supervisor | Y28: Departemen Head
A29: H | B29: - Holidays | H29: =COUNTIF($H$16:$AL$16,"H") -> 0 | J29: =COUNTIF($H$16:$AI$16,"H") -> 0
A30: AL | B30: - Annual Leave | H30: =COUNTIF($H$17:$AL$17,"AL") -> 0 | J30: =COUNTIF($L$17:$AI$17,"AL") -> 0
A31: S | B31: - Sick Leave | H31: =COUNTIF($H$18:$AG$18,"SL") -> 0 | J31: =COUNTIF($H$18:$AG$18,"SL") -> 0
A32: U | B32: - Unpaid Leave | H32: =COUNTIF($L$19:$AG$19,"U") -> 0 | J32: =COUNTIF($L$19:$AG$19,"U") -> 0
A33: C | B33: - Comp. Off | H33: =COUNTIF($L$20:$AG$20,"C") -> 0 | J33: =COUNTIF($L$20:$AG$20,"C") -> 0 | M33: =AC7 -> Annas Putra Anuraga | S33: =E9 -> Lailatul Fitriana R | Y33: =E8 -> Andhar Setiawan
A34: TOTAL | H34: =SUM(H27:I28) -> 168 | J34: =SUM(J27:K28) -> 21 | M34: Date 25 / 04 / 2026 | S34: Date 25 / 04 / 2026 | Y34: Date 25 / 04 / 2026
A36: Please Email This Form, Duly Signed To: | AE36: ** Leave application must be faxed with the timesheet!
A37: Attn: The HR Departement

Sheet MANDAYS CONSUMPTION REPORT
A2: MANDAYS CONSUMPTION REPORT
A3: =DATA!F7 -> PT Pesonna Optima Jasa
A6: Client Site | D6: : | E6: =DATA!F8 -> Divisi Pengembangan Aplikasi TI - PT Pegadaian | AA6: Squad | AD6: : | AE6: =DATA!F12 -> Pooling Core
A7: Work Unit | D7: : | E7: =DATA!F9 -> Dept. IT Bussines Analyst | AA7: Employee Name | AD7: : | AE7: =DATA!F5 -> Annas Putra Anuraga
A8: Dept. Head Name | D8: : | E8: =DATA!F10 -> Andhar Setiawan | AA8: Employee No. | AD8: : | AE8: =DATA!F6 -> POJ42050260
A9: Supervisor | D9: : | E9: =DATA!F11 -> Lailatul Fitriana R | AA9: Month | AD9: : | AE9: =DATA!F13 -> MARCH | AH9: to | AI9: =DATA!J13 -> APRIL
A10: A. Regular
A11: No. | B11: Date | D11: Description | V11: Duration of Work (Mandays) | X11: JIRA's Link | AF11: CRF/ G-Canvas No. | AI11: Ket.
A12: 1 | B12: 26/03/2026 | D12: Create gcanvas mini GM420326040 - Pengembangan Fitur Baru pada menu PASSION untuk Sync Nomor Rekening Emas | V12: 1 | X12: BATB-28136
A13: 2 | B13: 27/03/2026 | D13: Diskusi dengan mas andrea terkait project vss MT tring! | V13: 1 | X13: BATB-28137
D14: Update BRD BRD Q2 - Pengembangan menu manajemen disbursal pada aplikasi SPRINT untuk Repush VSS transaksi gadai minta tambah TRING! | X14: BATB-28138
D15: Meeting Weekly Core | X15: BATB-28140
A16: 3 | B16: 30/03/2026 | D16: Create gcanvas mini GM420326040 - Pengembangan Fitur Baru pada menu PASSION untuk Sync Nomor Rekening Emas | V16: 1 | X16: BATB-27430
A17: 4 | B17: 31/03/2026 | D17: support SIT Penambahan fitur sync rekening pada passion | V17: 1 | X17: BATB-27515
D18: create tiket open koneksi vpn | X18: BATB-27516
A19: 5 | B19: 01/04/2026 | D19: support sit sync rek emas | V19: 1 | X19: BATB-27585
A20: 6 | B20: 02/04/2026 | D20: Create mockup untuk BRD VSS MT Tring! | V20: 1 | X20: BATB-28142
D21: Update BRD BRD Q2 - Pengembangan menu manajemen disbursal pada aplikasi SPRINT untuk Repush VSS transaksi gadai minta tambah TRING! | X21: BATB-28143
D22: support sit sync rek emas | X22: BATB-28144
A23: 7 | B23: 06/04/2026 | D23: Synch Up after Launching Layanan Pegadaian Timor Leste | V23: 1 | X23: BATB-28145
D24: diskusi dengan mas andrea terkait improvement sync norek passion | X24: BATB-28146
A25: 8 | B25: 07/04/2026 | D25: Diskusi penambahan fitur sync rekening emas pada passion | V25: 1 | X25: BATB-28147
D26: Support SIT improvement order cetak | X26: BATB-28148
A27: 9 | B27: 08/04/2026 | D27: UAT GM420226023 - Penggantian Kodefikasi Rekening Stok Emas untuk Transaksi Order Cetak melalui Channel (RestCore) | V27: 1 | X27: BATB-28149
D28: support sit sync rek emas | X28: BATB-28150
A29: 10 | B29: 09/04/2026 | D29: support sit sync rek emas | V29: 1 | X29: BATB-28152
D30: support improvement timorleste | X30: BATB-28153
A31: 11 | B31: 10/04/2026 | D31: [ONLINE]Solution Planning Divisi PASTI | V31: 1 | X31: BATB-28154
D32: Uat improvement PASSION TimLes After Launching Layanan Operasional | X32: BATB-28155
A33: 12 | B33: 13/04/2026 | D33: weekly divisi | V33: 1 | X33: BATB-28156
D34: prepare doc deploy improvement timles | X34: BATB-28157
A35: 13 | B35: 14/04/2026 | D35: UAT - GM420326040 - Pengembangan Fitur Baru pada menu PASSION untuk Sync Nomor Rekening Emas | V35: 1 | X35: BATB-28159
D36: melengkapi gcanvas mini improvement passion timles | X36: BATB-28160
A37: 14 | B37: 15/04/2026 | D37: Support sit improvement timorleste | V37: 1 | X37: BATB-28750
A38: 15 | B38: 16/04/2026 | D38: Support sit improvement timorleste | V38: 1 | X38: BATB-28751
D39: prepare doc deploy improvement sync norek | X39: BATB-28753
A40: 16 | B40: 17/04/2026 | D40: support analisa requirement project middleware | V40: 1 | X40: BATB-28755
A41: 17 | B41: 20/04/2026 | D41: weekly departement | V41: 1 | X41: BATB-28757
D42: create dokumen gcanvas vss mt | X42: BATB-28759
A43: 18 | B43: 21/04/2026 | D43: create gcanvas vss mt | V43: 1 | X43: BATB-28761
...
